Workbook

Sheet Desincorporaciones (Resumen)
C3: Count of ¿Baja? (Emiliano OS) | D3: Column Labels
C4: Row Labels | D4: NO | E4: Grand Total
C5: NW | D5: 6 | E5: 6
C6: NE | D6: 23 | E6: 23
C7: WE | D7: 5 | E7: 5
C8: SE | D8: 4 | E8: 4
C9: CE | D9: 2 | E9: 2
C10: Grand Total | D10: 40 | E10: 40

Sheet Base
A1: CeCo | B1: Desc | C1: Región (16) | D1: GZ (20) | E1: Indirectos (37) | F1: ¿Baja Anterior? (Status-Activo24) | G1: ¿Baja? (Emiliano OS) | H1: Tipo de Cierre -Usuarios | I1: ¿BAJA MAE? (4) | J1: Inventarios | K1: Activo Fijo | L1: RH (7) | M1: V.Out | N1: ¿ Contrato Renta? | O1: Num. De Doc. Contrato | P1: ¿Status Licencias? | Q1: Licencias | R1: Agua (Centralizado ) | S1: Energía (Centralizado ) | T1: Energia Verde (6) | U1: CXC | V1: POS
A2: 300153569 | B2: Six Lucero | C2: SE | D2: GZ - YUCAM | E2: Directo | F2: Activo | G2: NO | H2: Natural | I2: SI | J2: 1166 | K2: 0 | L2: =_xlfn.XLOOKUP(A2,[2]Sheet1!$D$1:$D$65536,[2]Sheet1!$Q$1:$Q$65536,"Vacante") -> Vacante | M2: 0 | N2: =IF(O2<>"-","SI","NO") -> NO | O2: - | P2: =IF(Q2<>"-","SI","NO") -> SI | Q2: 6000012972 | R2: OK | S2: OK | T2: no | U2: =_xlfn.XLOOKUP(A2,[3]Sheet2!$A:$A,[3]Sheet2!$B:$B,0) -> -133172.37 | V2: CARGADO | W2: =_xlfn.XLOOKUP(A2,#REF!,#REF!) -> #REF!
A3: 301412270 | B3: JAL SIX I ABARROTES ARENAS | C3: WE | D3: GZ - JALISCO - NAYARIT | E3: Indirecto | F3: Activo | G3: NO | H3: Natural | I3: NO | J3: 0 | K3: 0 | L3: =_xlfn.XLOOKUP(A3,[2]Sheet1!$D$1:$D$65536,[2]Sheet1!$Q$1:$Q$65536,"Vacante") -> Vacante | M3: 0.01422 | N3: =IF(O3<>"-","SI","NO") -> NO | O3: - | P3: =IF(Q3<>"-","SI","NO") -> NO | Q3: - | R3: OK | S3: OK | T3: no | U3: =_xlfn.XLOOKUP(A3,[3]Sheet2!$A:$A,[3]Sheet2!$B:$B,0) -> -3712.76 | V3: CARGADO | W3: =_xlfn.XLOOKUP(A3,#REF!,#REF!) -> #REF!
A4: 301405252 | B4: JAL SIX I Abarrotes Valverde | C4: WE | D4: GZ - JALISCO - NAYARIT | E4: Indirecto | F4: Activo | G4: NO | H4: Natural | I4: NO | J4: 22052.94 | K4: 0 | L4: Activo | M4: 0.00474 | N4: =IF(O4<>"-","SI","NO") -> NO | O4: - | P4: =IF(Q4<>"-","SI","NO") -> NO | Q4: - | R4: OK | S4: OK | T4: no | U4: =_xlfn.XLOOKUP(A4,[3]Sheet2!$A:$A,[3]Sheet2!$B:$B,0) -> -12886.92 | V4: CARGADO | W4: =_xlfn.XLOOKUP(A4,#REF!,#REF!) -> #REF!
A5: 301495908 | B5: Ver Sur Six Beti | C5: SE | D5: GZ - TABASCO | E5: Directo | F5: Activo | G5: NO | H5: Natural | I5: NO | J5: 0 | K5: 67517.14 | L5: =_xlfn.XLOOKUP(A5,[2]Sheet1!$D$1:$D$65536,[2]Sheet1!$Q$1:$Q$65536,"Vacante") -> Vacante | M5: 0 | N5: =IF(O5<>"-","SI","NO") -> NO | O5: - | P5: =IF(Q5<>"-","SI","NO") -> NO | Q5: - | R5: ALTA | S5: ALTA | T5: NO | U5: =_xlfn.XLOOKUP(A5,[3]Sheet2!$A:$A,[3]Sheet2!$B:$B,0) -> 3602.95 | V5: CARGADO | W5: =_xlfn.XLOOKUP(A5,#REF!,#REF!) -> #REF!
A6: 301167103 | B6: Six Brody | C6: SE | D6: GZ - QROO | E6: Directo | F6: Activo | G6: NO | H6: Natural | I6: NO | J6: 0 | K6: 0 | L6: =_xlfn.XLOOKUP(A6,[2]Sheet1!$D$1:$D$65536,[2]Sheet1!$Q$1:$Q$65536,"Vacante") -> Vacante | M6: 0.01071 | N6: =IF(O6<>"-","SI","NO") -> NO | O6: - | P6: =IF(Q6<>"-","SI","NO") -> NO | Q6: - | R6: OK | S6: OK | T6: no | U6: =_xlfn.XLOOKUP(A6,[3]Sheet2!$A:$A,[3]Sheet2!$B:$B,0) -> -3745.19 | V6: CARGADO | W6: =_xlfn.XLOOKUP(A6,#REF!,#REF!) -> #REF!
A7: 300350538 | B7: La Cantera H3 | C7: SE | D7: GZ - OAXACA | E7: Directo | F7: Activo | G7: NO | H7: Natural | I7: NO | J7: 183.75 | K7: 0 | L7: =_xlfn.XLOOKUP(A7,[2]Sheet1!$D$1:$D$65536,[2]Sheet1!$Q$1:$Q$65536,"Vacante") -> Vacante | M7: 0 | N7: =IF(O7<>"-","SI","NO") -> NO | O7: - | P7: =IF(Q7<>"-","SI","NO") -> SI | Q7: 6000036150 | R7: ALTA | S7: ALTA | T7: NO | U7: =_xlfn.XLOOKUP(A7,[3]Sheet2!$A:$A,[3]Sheet2!$B:$B,0) -> 116741.34 | V7: CARGADO | W7: =_xlfn.XLOOKUP(A7,#REF!,#REF!) -> #REF!
A8: 300091113 | B8: Tsix Reforma | C8: NW | D8: GZ - SONORA | E8: Directo | F8: Activo | G8: NO | H8: Natural | I8: NO | J8: 0 | K8: 0 | L8: =_xlfn.XLOOKUP(A8,[2]Sheet1!$D$1:$D$65536,[2]Sheet1!$Q$1:$Q$65536,"Vacante") -> Vacante | M8: 0 | N8: =IF(O8<>"-","SI","NO") -> NO | O8: - | P8: =IF(Q8<>"-","SI","NO") -> NO | Q8: - | R8: OK | S8: OK | T8: no | U8: =_xlfn.XLOOKUP(A8,[3]Sheet2!$A:$A,[3]Sheet2!$B:$B,0) -> -21684.13 | V8: CARGADO | W8: =_xlfn.XLOOKUP(A8,#REF!,#REF!) -> #REF!
A9: 301427213 | B9: Son Six Michel | C9: NW | D9: GZ - SONORA | E9: Directo | F9: Activo | G9: NO | H9: Natural | I9: NO | J9: 205277.47 | K9: 0 | L9: =_xlfn.XLOOKUP(A9,[2]Sheet1!$D$1:$D$65536,[2]Sheet1!$Q$1:$Q$65536,"Vacante") -> Vacante | M9: 0 | N9: =IF(O9<>"-","SI","NO") -> NO | O9: - | P9: =IF(Q9<>"-","SI","NO") -> NO | Q9: - | R9: OK | S9: OK | T9: no | U9: =_xlfn.XLOOKUP(A9,[3]Sheet2!$A:$A,[3]Sheet2!$B:$B,0) -> 86.27 | V9: CARGADO | W9: =_xlfn.XLOOKUP(A9,#REF!,#REF!) -> #REF!
A10: 301371753 | B10: Bcs Six Ultramarinos La Luz | C10: NW | D10: GZ - BCS | E10: Directo | F10: Activo | G10: NO | H10: Natural | I10: NO | J10: 0 | K10: 0 | L10: =_xlfn.XLOOKUP(A10,[2]Sheet1!$D$1:$D$65536,[2]Sheet1!$Q$1:$Q$65536,"Vacante") -> Vacante | M10: 0 | N10: =IF(O10<>"-","SI","NO") -> NO | O10: - | P10: =IF(Q10<>"-","SI","NO") -> NO | Q10: - | R10: OK | S10: OK | T10: no | U10: =_xlfn.XLOOKUP(A10,[3]Sheet2!$A:$A,[3]Sheet2!$B:$B,0) -> -5628.37 | V10: CARGADO | W10: =_xlfn.XLOOKUP(A10,#REF!,#REF!) -> #REF!
A11: 300277204 | B11: Mini Super Ruiz | C11: NW | D11: GZ - BCS | E11: Directo | F11: Activo | G11: NO | H11: Natural | I11: NO | J11: 175883.84 | K11: 0 | L11: Activo | M11: 0 | N11: =IF(O11<>"-","SI","NO") -> NO | O11: - | P11: =IF(Q11<>"-","SI","NO") -> NO | Q11: - | R11: OK | S11: OK | T11: no | U11: =_xlfn.XLOOKUP(A11,[3]Sheet2!$A:$A,[3]Sheet2!$B:$B,0) -> 221.1 | V11: CARGADO | W11: =_xlfn.XLOOKUP(A11,#REF!,#REF!) -> #REF!
A12: 300086546 | B12: Super Six 005 Salvarcar | C12: NW | D12: GZ - JUAREZ | E12: Directo | F12: Activo | G12: NO | H12: Natural | I12: NO | J12: 16244.14 | K12: 0 | L12: =_xlfn.XLOOKUP(A12,[2]Sheet1!$D$1:$D$65536,[2]Sheet1!$Q$1:$Q$65536,"Vacante") -> Vacante | M12: 0.08568 | N12: =IF(O12<>"-","SI","NO") -> NO | O12: - | P12: =IF(Q12<>"-","SI","NO") -> NO | Q12: - | R12: OK | S12: OK | T12: no | U12: =_xlfn.XLOOKUP(A12,[3]Sheet2!$A:$A,[3]Sheet2!$B:$B,0) -> -49171.91 | V12: CARGADO | W12: =_xlfn.XLOOKUP(A12,#REF!,#REF!) -> #REF!
A13: 300986721 | B13: NL Six 4 Montemayor | C13: NE | D13: GZ - NUEVO LEON | E13: Directo | F13: Activo | G13: NO | H13: Natural | I13: NO | J13: 3566.2 | K13: 15891.78 | L13: =_xlfn.XLOOKUP(A13,[2]Sheet1!$D$1:$D$65536,[2]Sheet1!$Q$1:$Q$65536,"Vacante") -> Vacante | M13: 0 | N13: =IF(O13<>"-","SI","NO") -> NO | O13: - | P13: =IF(Q13<>"-","SI","NO") -> SI | Q13: 6000025909-6000109185 | R13: ALTA | S13: ALTA | T13: NO | U13: =_xlfn.XLOOKUP(A13,[3]Sheet2!$A:$A,[3]Sheet2!$B:$B,0) -> 9097.17 | V13: CARGADO | W13: =_xlfn.XLOOKUP(A13,#REF!,#REF!) -> #REF!
A14: 300835078 | B14: Tkt Six Ocaso | C14: NE | D14: GZ - NUEVO LEON | E14: Directo | F14: Activo | G14: NO | H14: Natural | I14: NO | J14: 1550.71 | K14: 14137.09 | L14: =_xlfn.XLOOKUP(A14,[2]Sheet1!$D$1:$D$65536,[2]Sheet1!$Q$1:$Q$65536,"Vacante") -> Vacante | M14: 0 | N14: =IF(O14<>"-","SI","NO") -> NO | O14: - | P14: =IF(Q14<>"-","SI","NO") -> SI | Q14: 6000072344-6000108417 | R14: ALTA | S14: ALTA | T14: Sí | U14: =_xlfn.XLOOKUP(A14,[3]Sheet2!$A:$A,[3]Sheet2!$B:$B,0) -> 1200.99 | V14: CARGADO | W14: =_xlfn.XLOOKUP(A14,#REF!,#REF!) -> #REF!
A15: 301335082 | B15: NI Six 9 Villarreal | C15: NE | D15: GZ - NUEVO LEON | E15: Directo | F15: Activo | G15: NO | H15: Natural | I15: NO | J15: 0 | K15: 0 | L15: Activo | M15: 0 | N15: =IF(O15<>"-","SI","NO") -> NO | O15: - | P15: =IF(Q15<>"-","SI","NO") -> SI | Q15: 6000101346 | R15: ALTA | S15: ALTA | T15: NO | U15: =_xlfn.XLOOKUP(A15,[3]Sheet2!$A:$A,[3]Sheet2!$B:$B,0) -> 88194.15 | V15: PENDIENTE | W15: =_xlfn.XLOOKUP(A15,#REF!,#REF!) -> #REF!
A16: 301413729 | B16: NL SIX 20 Serafin peña | C16: NE | D16: GZ - NUEVO LEON | E16: Directo | F16: Activo | G16: NO | H16: Natural | I16: NO | J16: 92744.06 | K16: 14663.24 | L16: Activo | M16: 0.8314 | N16: =IF(O16<>"-","SI","NO") -> NO | O16: - | P16: =IF(Q16<>"-","SI","NO") -> SI | Q16: 6000029416-6000108480 | R16: ALTA | S16: ALTA | T16: NO | U16: =_xlfn.XLOOKUP(A16,[3]Sheet2!$A:$A,[3]Sheet2!$B:$B,0) -> 8146.86 | V16: CARGADO | W16: =_xlfn.XLOOKUP(A16,#REF!,#REF!) -> #REF!
A17: 301339034 | B17: NL SIX 9 TULIPAN | C17: NE | D17: GZ - NUEVO LEON | E17: Directo | F17: Activo | G17: NO | H17: Natural | I17: NO | J17: 0 | K17: 0 | L17: Activo | M17: 0 | N17: =IF(O17<>"-","SI","NO") -> NO | O17: - | P17: =IF(Q17<>"-","SI","NO") -> SI | Q17: 6000097115-6000111368 | R17: ALTA | S17: ALTA | T17: NO | U17: =_xlfn.XLOOKUP(A17,[3]Sheet2!$A:$A,[3]Sheet2!$B:$B,0) -> 20060.3 | V17: CARGADO | W17: =_xlfn.XLOOKUP(A17,#REF!,#REF!) -> #REF!
A18: 301355832 | B18: NL SIX 9 FRAY | C18: NE | D18: GZ - NUEVO LEON | E18: Directo | F18: Activo | G18: NO | H18: Natural | I18: NO | J18: 0 | K18: 0 | L18: Activo | M18: 0 | N18: =IF(O18<>"-","SI","NO") -> NO | O18: - | P18: =IF(Q18<>"-","SI","NO") -> NO | Q18: - | R18: OK | S18: OK | T18: no | U18: =_xlfn.XLOOKUP(A18,[3]Sheet2!$A:$A,[3]Sheet2!$B:$B,0) -> 6575.99 | V18: CARGADO | W18: =_xlfn.XLOOKUP(A18,#REF!,#REF!) -> #REF!
A19: 301322278 | B19: NL Six 8 Libramiento | C19: NE | D19: GZ - NUEVO LEON | E19: Directo | F19: Activo | G19: NO | H19: Natural | I19: NO | J19: 3572.58 | K19: 0 | L19: =_xlfn.XLOOKUP(A19,[2]Sheet1!$D$1:$D$65536,[2]Sheet1!$Q$1:$Q$65536,"Vacante") -> Vacante | M19: 0 | N19: =IF(O19<>"-","SI","NO") -> NO | O19: - | P19: =IF(Q19<>"-","SI","NO") -> SI | Q19: 6000097039-6000109285 | R19: ALTA | S19: ALTA | T19: NO | U19: =_xlfn.XLOOKUP(A19,[3]Sheet2!$A:$A,[3]Sheet2!$B:$B,0) -> -5903.47 | V19: CARGADO | W19: =_xlfn.XLOOKUP(A19,#REF!,#REF!) -> #REF!
A20: 301272951 | B20: COA SIX 8 OAXACA | C20: NE | D20: GZ - COAHUILA | E20: Directo | F20: Activo | G20: NO | H20: Natural | I20: NO | J20: 1513.25 | K20: 0 | L20: =_xlfn.XLOOKUP(A20,[2]Sheet1!$D$1:$D$65536,[2]Sheet1!$Q$1:$Q$65536,"Vacante") -> Vacante | M20: 0 | N20: =IF(O20<>"-","SI","NO") -> NO | O20: - | P20: =IF(Q20<>"-","SI","NO") -> NO | Q20: - | R20: ALTA | S20: ALTA | T20: NO | U20: =_xlfn.XLOOKUP(A20,[3]Sheet2!$A:$A,[3]Sheet2!$B:$B,0) -> -14250.81 | V20: CARGADO | W20: =_xlfn.XLOOKUP(A20,#REF!,#REF!) -> #REF!
A21: 301329303 | B21: NI Six9 Mallorca | C21: NE | D21: GZ - NUEVO LEON | E21: Directo | F21: Activo | G21: NO | H21: Natural | I21: NO | J21: 3766.77 | K21: 0 | L21: =_xlfn.XLOOKUP(A21,[2]Sheet1!$D$1:$D$65536,[2]Sheet1!$Q$1:$Q$65536,"Vacante") -> Vacante | M21: 0 | N21: =IF(O21<>"-","SI","NO") -> NO | O21: - | P21: =IF(Q21<>"-","SI","NO") -> SI | Q21: 6000097354-6000111276 | R21: ALTA | S21: ALTA | T21: NO | U21: =_xlfn.XLOOKUP(A21,[3]Sheet2!$A:$A,[3]Sheet2!$B:$B,0) -> -50998.61 | V21: CARGADO | W21: =_xlfn.XLOOKUP(A21,#REF!,#REF!) -> #REF!
A22: 300844017 | B22: Tkt Six Roberto G Sada | C22: NE | D22: GZ - NUEVO LEON | E22: Directo | F22: Activo | G22: NO | H22: Natural | I22: NO | J22: 1828.67 | K22: 8953.31 | L22: =_xlfn.XLOOKUP(A22,[2]Sheet1!$D$1:$D$65536,[2]Sheet1!$Q$1:$Q$65536,"Vacante") -> Vacante | M22: 0 | N22: =IF(O22<>"-","SI","NO") -> NO | O22: - | P22: =IF(Q22<>"-","SI","NO") -> SI | Q22: 6000072451-6000109291 | R22: ALTA | S22: ALTA | T22: Sí | U22: =_xlfn.XLOOKUP(A22,[3]Sheet2!$A:$A,[3]Sheet2!$B:$B,0) -> -21899.54 | V22: CARGADO | W22: =_xlfn.XLOOKUP(A22,#REF!,#REF!) -> #REF!
A23: 300825384 | B23: Tam Six Dos Arroyos | C23: NE | D23: GZ - VERACRUZ NORTE | E23: Directo | F23: Activo | G23: NO | H23: Natural | I23: NO | J23: 625 | K23: 0 | L23: =_xlfn.XLOOKUP(A23,[2]Sheet1!$D$1:$D$65536,[2]Sheet1!$Q$1:$Q$65536,"Vacante") -> Vacante | M23: 0 | N23: =IF(O23<>"-","SI","NO") -> NO | O23: - | P23: =IF(Q23<>"-","SI","NO") -> SI | Q23: 6000073299-6000073745 | R23: ALTA | S23: ALTA | T23: Sí | U23: =_xlfn.XLOOKUP(A23,[3]Sheet2!$A:$A,[3]Sheet2!$B:$B,0) -> -15312.52 | V23: CARGADO | W23: =_xlfn.XLOOKUP(A23,#REF!,#REF!) -> #REF!
A24: 301465692 | B24: Nl Six 21 Rulo | C24: NE | D24: GZ - NUEVO LEON | E24: Directo | F24: Activo | G24: NO | H24: Natural | I24: NO | J24: 0 | K24: 47947.94 | L24: =_xlfn.XLOOKUP(A24,[2]Sheet1!$D$1:$D$65536,[2]Sheet1!$Q$1:$Q$65536,"Vacante") -> Vacante | M24: 0 | N24: =IF(O24<>"-","SI","NO") -> NO | O24: - | P24: =IF(Q24<>"-","SI","NO") -> SI | Q24: 6000105442-6000110220 | R24: ALTA | S24: ALTA | T24: NO | U24: =_xlfn.XLOOKUP(A24,[3]Sheet2!$A:$A,[3]Sheet2!$B:$B,0) -> 14777.35 | V24: CARGADO | W24: =_xlfn.XLOOKUP(A24,#REF!,#REF!) -> #REF!
A25: 300950777 | B25: NL Six Winchester | C25: NE | D25: GZ - NUEVO LEON | E25: Directo | F25: Activo | G25: NO | H25: Natural | I25: NO | J25: 2750.63 | K25: 0 | L25: =_xlfn.XLOOKUP(A25,[2]Sheet1!$D$1:$D$65536,[2]Sheet1!$Q$1:$Q$65536,"Vacante") -> Vacante | M25: 0 | N25: =IF(O25<>"-","SI","NO") -> NO | O25: - | P25: =IF(Q25<>"-","SI","NO") -> SI | Q25: 6000072613-6000111515 | R25: ALTA | S25: ALTA | T25: Sí | U25: =_xlfn.XLOOKUP(A25,[3]Sheet2!$A:$A,[3]Sheet2!$B:$B,0) -> 11057.13 | V25: CARGADO | W25: =_xlfn.XLOOKUP(A25,#REF!,#REF!) -> #REF!
A26: 300848899 | B26: Tkt Six Rancho | C26: NE | D26: GZ - NUEVO LEON | E26: Directo | F26: Activo | G26: NO | H26: Natural | I26: NO | J26: 3021.09 | K26: 7755.06 | L26: Activo | M26: 0 | N26: =IF(O26<>"-","SI","NO") -> NO | O26: - | P26: =IF(Q26<>"-","SI","NO") -> SI | Q26: 6000072503-6000108455 | R26: ALTA | S26: ALTA | T26: Sí | U26: =_xlfn.XLOOKUP(A26,[3]Sheet2!$A:$A,[3]Sheet2!$B:$B,0) -> -1951.32 | V26: CARGADO | W26: =_xlfn.XLOOKUP(A26,#REF!,#REF!) -> #REF!
A27: 300843639 | B27: Tkt Six Los Reales | C27: NE | D27: GZ - NUEVO LEON | E27: Directo | F27: Activo | G27: NO | H27: Natural | I27: NO | J27: 217960.89 | K27: 0 | L27: Activo | M27: 18.15645 | N27: =IF(O27<>"-","SI","NO") -> NO | O27: - | P27: =IF(Q27<>"-","SI","NO") -> SI | Q27: 6000072433-6000109268 | R27: ALTA | S27: ALTA | T27: Sí | U27: =_xlfn.XLOOKUP(A27,[3]Sheet2!$A:$A,[3]Sheet2!$B:$B,0) -> 4274.69 | V27: CARGADO | W27: =_xlfn.XLOOKUP(A27,#REF!,#REF!) -> #REF!
A28: 301326883 | B28: San Isidro | C28: NE | D28: GZ - NUEVO LEON | E28: Directo | F28: Activo | G28: NO | H28: Natural | I28: NO | J28: 13517.69 | K28: 0 | L28: =_xlfn.XLOOKUP(A28,[2]Sheet1!$D$1:$D$65536,[2]Sheet1!$Q$1:$Q$65536,"Vacante") -> Vacante | M28: 0 | N28: =IF(O28<>"-","SI","NO") -> NO | O28: - | P28: =IF(Q28<>"-","SI","NO") -> SI | Q28: 6000101276-6000110726 | R28: ALTA | S28: ALTA | T28: NO | U28: =_xlfn.XLOOKUP(A28,[3]Sheet2!$A:$A,[3]Sheet2!$B:$B,0) -> 2508.93 | V28: CARGADO | W28: =_xlfn.XLOOKUP(A28,#REF!,#REF!) -> #REF!
A29: 301020640 | B29: NL Six 4 Cofre | C29: NE | D29: GZ - NUEVO LEON | E29: Directo | F29: Activo | G29: NO | H29: Natural | I29: NO | J29: 4182.75 | K29: 5592.4 | L29: =_xlfn.XLOOKUP(A29,[2]Sheet1!$D$1:$D$65536,[2]Sheet1!$Q$1:$Q$65536,"Vacante") -> Vacante | M29: 0 | N29: =IF(O29<>"-","SI","NO") -> NO | O29: - | P29: =IF(Q29<>"-","SI","NO") -> SI | Q29: 6000072832-6000108698 | R29: ALTA | S29: ALTA | T29: Sí | U29: =_xlfn.XLOOKUP(A29,[3]Sheet2!$A:$A,[3]Sheet2!$B:$B,0) -> -51549.58 | V29: CARGADO | W29: =_xlfn.XLOOKUP(A29,#REF!,#REF!) -> #REF!
A30: 300769339 | B30: Dur Trebol | C30: NE | D30: GZ - DURANGO | E30: Directo | F30: Activo | G30: NO | H30: Natural | I30: NO | J30: 2272.43 | K30: 0 | L30: =_xlfn.XLOOKUP(A30,[2]Sheet1!$D$1:$D$65536,[2]Sheet1!$Q$1:$Q$65536,"Vacante") -> Vacante | M30: 0 | N30: =IF(O30<>"-","SI","NO") -> NO | O30: - | P30: =IF(Q30<>"-","SI","NO") -> NO | Q30: - | R30: ALTA | S30: ALTA | T30: Sí | U30: =_xlfn.XLOOKUP(A30,[3]Sheet2!$A:$A,[3]Sheet2!$B:$B,0) -> -433.53 | V30: CARGADO | W30: =_xlfn.XLOOKUP(A30,#REF!,#REF!) -> #REF!
A31: 301387726 | B31: Dur Six 20 Constelaciones | C31: NE | D31: GZ - DURANGO | E31: Directo | F31: Activo | G31: NO | H31: Natural | I31: NO | J31: 177403.97 | K31: 70.27 | L31: Activo | M31: 29.14834 | N31: =IF(O31<>"-","SI","NO") -> NO | O31: - | P31: =IF(Q31<>"-","SI","NO") -> SI | Q31: 6000032739 | R31: ALTA | S31: ALTA | T31: NO | U31: =_xlfn.XLOOKUP(A31,[3]Sheet2!$A:$A,[3]Sheet2!$B:$B,0) -> 12117.97 | V31: CARGADO | W31: =_xlfn.XLOOKUP(A31,#REF!,#REF!) -> #REF!
A32: 301950297 | B32: NL SIX 24 ZITA | C32: NE | D32: GZ - NUEVO LEON | E32: Directo | F32: Activo | G32: NO | H32: Natural | I32: NO | J32: 0 | K32: 288520.49 | L32: =_xlfn.XLOOKUP(A32,[2]Sheet1!$D$1:$D$65536,[2]Sheet1!$Q$1:$Q$65536,"Vacante") -> Vacante | M32: 0 | N32: =IF(O32<>"-","SI","NO") -> NO | O32: - | P32: =IF(Q32<>"-","SI","NO") -> SI | Q32: 6000112646-6000112671 | R32: ALTA | S32: ALTA | T32: NO | U32: =_xlfn.XLOOKUP(A32,[3]Sheet2!$A:$A,[3]Sheet2!$B:$B,0) -> -1.83 | V32: CARGADO | W32: =_xlfn.XLOOKUP(A32,#REF!,#REF!) -> #REF!
A33: 300842858 | B33: Tkt Six Bautista | C33: NE | D33: GZ - NUEVO LEON | E33: Directo | F33: Activo | G33: NO | H33: Natural | I33: NO | J33: 0 | K33: 0 | L33: =_xlfn.XLOOKUP(A33,[2]Sheet1!$D$1:$D$65536,[2]Sheet1!$Q$1:$Q$65536,"Vacante") -> Vacante | M33: 0 | N33: =IF(O33<>"-","SI","NO") -> NO | O33: - | P33: =IF(Q33<>"-","SI","NO") -> SI | Q33: 6000072419-6000108490 | R33: OK | S33: OK | T33: no | U33: =_xlfn.XLOOKUP(A33,[3]Sheet2!$A:$A,[3]Sheet2!$B:$B,0) -> 7286.88 | V33: CARGADO | W33: =_xlfn.XLOOKUP(A33,#REF!,#REF!) -> #REF!
A34: 300841858 | B34: Tkt Six Nispero | C34: NE | D34: GZ - NUEVO LEON | E34: Directo | F34: Activo | G34: NO | H34: Natural | I34: NO | J34: 0 | K34: 0 | L34: =_xlfn.XLOOKUP(A34,[2]Sheet1!$D$1:$D$65536,[2]Sheet1!$Q$1:$Q$65536,"Vacante") -> Vacante | M34: 0 | N34: =IF(O34<>"-","SI","NO") -> NO | O34: - | P34: =IF(Q34<>"-","SI","NO") -> SI | Q34: 6000072386-6000111441 | R34: ALTA | S34: ALTA | T34: Sí | U34: =_xlfn.XLOOKUP(A34,[3]Sheet2!$A:$A,[3]Sheet2!$B:$B,0) -> 44410.51 | V34: CARGADO | W34: =_xlfn.XLOOKUP(A34,#REF!,#REF!) -> #REF!
A35: 300824109 | B35: Tam Six Monterrey | C35: NE | D35: GZ - VERACRUZ NORTE | E35: Directo | F35: Activo | G35: NO | H35: Natural | I35: NO | J35: 992.58 | K35: 26172.79 | L35: =_xlfn.XLOOKUP(A35,[2]Sheet1!$D$1:$D$65536,[2]Sheet1!$Q$1:$Q$65536,"Vacante") -> Vacante | M35: 0 | N35: =IF(O35<>"-","SI","NO") -> NO | O35: - | P35: =IF(Q35<>"-","SI","NO") -> SI | Q35: 6000081213-6000102422 | R35: ALTA | S35: ALTA | T35: Sí | U35: =_xlfn.XLOOKUP(A35,[3]Sheet2!$A:$A,[3]Sheet2!$B:$B,0) -> -10459.52 | V35: CARGADO | W35: =_xlfn.XLOOKUP(A35,#REF!,#REF!) -> #REF!
A36: 301432975 | B36: Chi Six La Camarguense | C36: NW | D36: GZ - JUAREZ | E36: Directo | F36: Activo | G36: NO | H36: Natural | I36: NO | J36: 264 | K36: 0 | L36: =_xlfn.XLOOKUP(A36,[2]Sheet1!$D$1:$D$65536,[2]Sheet1!$Q$1:$Q$65536,"Vacante") -> Vacante | M36: 3.22942 | N36: =IF(O36<>"-","SI","NO") -> NO | O36: - | P36: =IF(Q36<>"-","SI","NO") -> NO | Q36: - | R36: OK | S36: OK | T36: no | U36: =_xlfn.XLOOKUP(A36,[3]Sheet2!$A:$A,[3]Sheet2!$B:$B,0) -> 19086.93 | V36: CARGADO | W36: =_xlfn.XLOOKUP(A36,#REF!,#REF!) -> #REF!
A37: 302064031 | B37: VDM SIX I MARKET YAKSE | C37: CE | D37: GZ - VDM PV | E37: Indirecto | F37: Activo | G37: NO | H37: Natural | I37: NO | J37: 24089.63 | K37: 46694.46 | L37: Activo | M37: 0.01204 | N37: =IF(O37<>"-","SI","NO") -> NO | O37: - | P37: =IF(Q37<>"-","SI","NO") -> NO | Q37: - | R37: OK | S37: OK | T37: no | U37: =_xlfn.XLOOKUP(A37,[3]Sheet2!$A:$A,[3]Sheet2!$B:$B,0) -> 1698.79 | V37: CARGADO | W37: =_xlfn.XLOOKUP(A37,#REF!,#REF!) -> #REF!
A38: 300222066 | B38: PUE Six Ecologico | C38: CE | D38: GZ - PUEBLA | E38: Directo | F38: Activo | G38: NO | H38: Natural | I38: SI | J38: 228 | K38: 0 | L38: =_xlfn.XLOOKUP(A38,[2]Sheet1!$D$1:$D$65536,[2]Sheet1!$Q$1:$Q$65536,"Vacante") -> Vacante | M38: 0 | N38: =IF(O38<>"-","SI","NO") -> NO | O38: - | P38: =IF(Q38<>"-","SI","NO") -> NO | Q38: - | R38: OK | S38: OK | T38: no | U38: =_xlfn.XLOOKUP(A38,[3]Sheet2!$A:$A,[3]Sheet2!$B:$B,0) -> -41333.34 | V38: CARGADO | W38: =_xlfn.XLOOKUP(A38,#REF!,#REF!) -> #REF!
A39: 301515140 | B39: VDM SIX I San Agustin | C39: CE | D39: GZ - VDM PV | E39: Indirecto | F39: Activo | G39: NO | H39: Natural | I39: NO | J39: 18438.86 | K39: 0 | L39: Activo | M39: 0.89767 | N39: =IF(O39<>"-","SI","NO") -> NO | O39: - | P39: =IF(Q39<>"-","SI","NO") -> NO | Q39: - | R39: OK | S39: OK | T39: no | U39: =_xlfn.XLOOKUP(A39,[3]Sheet2!$A:$A,[3]Sheet2!$B:$B,0) -> 5502.66 | V39: CARGADO | W39: =_xlfn.XLOOKUP(A39,#REF!,#REF!) -> #REF!
A40: 301583668 | B40: VDM SIX I SUPER LUPITA | C40: CE | D40: GZ - VDM PV | E40: Indirecto | F40: Activo | G40: NO | H40: Natural | I40: NO | J40: 0 | K40: 0 | L40: Activo | M40: 0 | N40: =IF(O40<>"-","SI","NO") -> NO | O40: - | P40: =IF(Q40<>"-","SI","NO") -> NO | Q40: - | R40: OK | S40: OK | T40: no | U40: =_xlfn.XLOOKUP(A40,[3]Sheet2!$A:$A,[3]Sheet2!$B:$B,0) -> 24.05 | V40: CARGADO | W40: =_xlfn.XLOOKUP(A40,#REF!,#REF!) -> #REF!
...

Sheet Bajas Oficiales
A2: z
A3: CeCo | B3: Descripción | C3: Región SIX | D3: GZ SIX | E3: Desc JOS (Resp) (19) | F3: Desc ACS (Resp) (21) | G3: Madura (22) | H3: Tipo de Cierre | I3: Status | J3: Mes Baja | K3: Tipo Baja
A4: 300566218 | B4: Ags Six San Pancho | C4: OCCIDENTE | D4: Ags-Zac-SLP | E4: Vacante CPCP27 (SLP-AGS-ZAC) | F4: Edgar Garcia Corpus | G4: Madura | H4: Plan | I4: Desincorporado | J4: 45292 | K4: Baja Total
A5: 301154436 | B5: Tam Six 6 Constitucion | C5: NORESTE | D5: Tamps Sur/Ver Nte | E5: Vacante CPCP39 (TAMAULIPAS - VER NTE) | F5: Gabriela Estefani Amaya Escobar | G5: Madura | H5: Legal | I5: Desincorporado | J5: 45292 | K5: Baja Total
A6: 301290361 | B6: COA SIX 8 CRISTIAN | C6: NORESTE | D6: Coahuila | E6: Manuel Ruiz Soto (DUR) | F6: Rogelio Ruiz Garcia | G6: Madura | H6: Natural | I6: Desincorporado | J6: 45292 | K6: Baja Total
A7: 301404686 | B7: Dur Six 20 Cuencame | C7: NORESTE | D7: Durango | E7: Manuel Ruiz Soto (DUR) | F7: Miguel Amador Rodriguez | G7: Madura | H7: Region Plan | I7: Desincorporado | J7: 45292 | K7: Baja Total
A8: 301320771 | B8: TAM SIX 8 Jesi | C8: NORESTE | D8: Tamps Sur/Ver Nte | E8: Vacante CPCP39 (TAMAULIPAS - VER NTE) | F8: Gabriela Estefani Amaya Escobar | G8: Madura | H8: Natural | I8: Desincorporado | J8: 45292 | K8: Baja Total
A9: 301397292 | B9: PUE SIX VOLCANES | C9: CENTRO | D9: Puebla - Tlaxcala | E9: María G. Flores (PUE - TLX - HGO) | F9: Silva Celma Fernando | G9: Madura | H9: Natural | I9: Desincorporado | J9: 45292 | K9: Baja Total
A10: 301502702 | B10: Vdm Six I La 0510 | C10: CENTRO | D10: Valle de Mex | E10: Arturo Nava (VDM SIX I) | F10: Olivares De Aquino Diana Monserrat | G10: No Madura (Exp 22) | H10: Natural | I10: Desincorporado | J10: 45292 | K10: Baja Total
A11: 301590789 | B11: VDM SIX I EL LLAVERO | C11: CENTRO | D11: Valle de Mex | E11: Arturo Nava (VDM SIX I) | F11: Olivares De Aquino Diana Monserrat | G11: No Madura (Exp 23) | H11: Natural | I11: Desincorporado | J11: 45292 | K11: Baja Total
A12: 301632756 | B12: Vdm Six I Ariadna | C12: CENTRO | D12: Valle de Mex | E12: Arturo Nava (VDM SIX I) | F12: Ortiz Mota Georgina Eloisa | G12: No Madura (Exp 23) | H12: Natural | I12: Desincorporado | J12: 45292 | K12: Baja Total
A13: 300392224 | B13: CVF Lazaro Cardenas | C13: CENTRO | D13: Estado de México | E13: Gustavo Serrano (EDOMEX - MOR) | F13: Bernal Nava Maria de Jesus | G13: Madura | H13: Natural | I13: Desincorporado | J13: 45292 | K13: Baja Total
A14: 300064957 | B14: Tkt Six TS AB | C14: NOROESTE | D14: Baja California Nte | E14: Edna Méndez (BCN 2) | F14: Jorge Ernesto Sandoval Lizarraga | G14: Madura | H14: Natural | I14: Desincorporado | J14: 45292 | K14: Baja Total
A15: 301476984 | B15: Chi Six Miguel | C15: NOROESTE | D15: Juárez | E15: Gerardo Borunda (JUAREZ) | F15: Hiram Valentin Nuñez Esquer | G15: Pre-operativo | H15: Natural | I15: Desincorporado | J15: 45292 | K15: Baja Total
... A216: 301346617 | B216: MOR SIX 3 Marias Azteca | C216: CENTRO | D216: Guerrero - Morelos | E216: Gustavo Serrano (EDOMEX - MOR) | F216: Palacios Zendeja Jesus | G216: Madura | H216: Plan | I216: Desincorporado | J216: 45474 | K216: Baja Total
A217: 300098317 | B217: Super Six la Trucha | C217: NOROESTE | D217: Chihuahua | E217: Felipe Lechuga (CHIH NTE) | F217: 0 | G217: Madura | H217: Natural | I217: Desincorporado | J217: 45474 | K217: Baja Total
A218: 300250995 | B218: VER SIX Agencia Tuxpan | C218: NORESTE | D218: Tamps Sur/Ver Nte | E218: Javier Huerta (TAMAULIPAS - VER NTE) | F218: Bianca Denisse Sosa Rodriguez | G218: Madura | H218: Legal | I218: Desincorporado | J218: 45474 | K218: Baja Total
A219: 301558928 | B219: NL SIX 23 OPERACIONES | C219: NORESTE | D219: Nuevo León | E219: Edith Hernandez (NL Ote) | F219: Jhonatan Garduño | G219: No Madura (Exp 23) | H219: Legal | I219: Desincorporado | J219: 45474 | K219: Baja Total
A220: 300925288 | B220: Sin Six Super Mini Super | C220: NOROESTE | D220: Sinaloa | E220: Sergio Luis Inzunza Rosas (SINALOA NTE 3) | F220: Daniel Lopez Espinoza | G220: Madura | H220: Natural | I220: Desincorporado | J220: 45474 | K220: Baja Total
A221: 301521563 | B221: Sin Six MS La Palmita De Mojolo | C221: NOROESTE | D221: Sinaloa | E221: Jorge Manzanarez (SINALOA CTO FORANEO) | F221: Martin Alonso Garcia Jimenez | G221: Madura | H221: Natural | I221: Desincorporado | J221: 45474 | K221: Baja Total
A222: 300221921 | B222: PUE Six Camino a Tlaltepango | C222: CENTRO | D222: Puebla - Tlaxcala | E222: María G. Flores (PUE - TLX - HGO) | F222: Silva Celma Fernando | G222: Madura | H222: Natural | I222: Desincorporado | J222: 45474 | K222: Baja Total
A223: 301044759 | B223: NL Six 4 Emiliano | C223: NORESTE | D223: Nuevo León | E223: Edith Hernandez (NL Ote) | F223: Roberto Carlos Cantú Gallardo | G223: Madura | H223: Plan | I223: Desincorporado | J223: 45474 | K223: Baja Total
A224: 301352390 | B224: NL Six 9 Coors | C224: NORESTE | D224: Nuevo León | E224: Edith Hernandez (NL Ote) | F224: Sergio Galarza Hernandez | G224: Madura | H224: Plan | I224: Desincorporado | J224: 45474 | K224: Baja Total
A225: 301301243 | B225: Tam Six 8 Huertas | C225: NORESTE | D225: Tamps Sur/Ver Nte | E225: Javier Huerta (TAMAULIPAS - VER NTE) | F225: Juan de Dios Estrada Martinez | G225: Madura | H225: Legal | I225: Desincorporado | J225: 45474 | K225: Baja Total
A226: 301391241 | B226: Jal Six I Ab Boris | C226: OCCIDENTE | D226: Jal - Col - Nay | E226: Miguel Antonio Luna Meza (JAL IND) | F226: Victor Garcia Abundis | G226: Madura | H226: Natural | I226: Desincorporado | J226: 45474 | K226: Baja Total
A227: 301354658 | B227: JAL SIX LOS CHUPERAMIGOS | C227: OCCIDENTE | D227: Jal - Col - Nay | E227: Miguel Antonio Luna Meza (JAL IND) | F227: Misael Diaz Nuño | G227: Madura | H227: Natural | I227: Desincorporado | J227: 45474 | K227: Baja Total
A228: 301442803 | B228: VDM SIX I SUPER YA LA CAVITA | C228: CENTRO | D228: Valle de Mex | E228: Arturo Nava (VDM SIX I) | F228: Quiroz Ruiz Joafh Alberto | G228: Madura | H228: Natural | I228: Desincorporado | J228: 45474 | K228: Baja Total
A229: 301482111 | B229: VDM Six El Pecado | C229: CENTRO | D229: Valle de Mex | E229: Arturo Nava (VDM SIX I) | F229: Sanchez Flores Christopher | G229: Madura | H229: Natural | I229: Desincorporado | J229: 45474 | K229: Baja Total
... A800: 301744773 | B800: Vdm Six I Los Gonzalez | C800: CENTRO | D800: Valle de Mex | E800: Arturo Nava (VDM SIX I) | F800: Leal Garcia Maria del Carmen | G800: No Madura (Exp 23) | H800: Natural | I800: Desincorporado | J800: 45658 | K800: Baja Total
A801: 300948721 | B801: Jal Six Pelee | C801: OCCIDENTE | D801: Jal - Col - Nay | E801: Nancy Velez (JAL - COL - NAY) | F801: Jose Alberto Rodriguez Arias | G801: Madura | H801: =_xlfn.XLOOKUP(A801,Base!A:A,Base!H:H,"Plan") -> Plan | I801: Desincorporado | J801: 45689 | K801: Baja Total
A802: 301563715 | B802: JAL SIX TEPA ALAMEDA | C802: OCCIDENTE | D802: Jal - Col - Nay | E802: Nancy Velez (JAL - COL - NAY) | F802: Miguel Hernando Plancarte Lara | G802: Madura | H802: =_xlfn.XLOOKUP(A802,Base!A:A,Base!H:H,"Plan") -> Plan | I802: Desincorporado | J802: 45689 | K802: Baja Total
A803: 300124039 | B803: Tkt Six Avenida Mexico | C803: OCCIDENTE | D803: Jal - Col - Nay | E803: Nancy Velez (JAL - COL - NAY) | F803: Kevin Yovani Parra Gonzalez | G803: Madura | H803: =_xlfn.XLOOKUP(A803,Base!A:A,Base!H:H,"Plan") -> Plan | I803: Desincorporado | J803: 45689 | K803: Baja Total
A804: 301485828 | B804: Jal Six Ixtapa | C804: OCCIDENTE | D804: Jal - Col - Nay | E804: Nancy Velez (JAL - COL - NAY) | F804: Jose armando Vargas H. | G804: Madura | H804: =_xlfn.XLOOKUP(A804,Base!A:A,Base!H:H,"Plan") -> Plan | I804: Desincorporado | J804: 45689 | K804: Baja Total
A805: 300619899 | B805: Jal Six Monte Largo | C805: OCCIDENTE | D805: Jal - Col - Nay | E805: Nancy Velez (JAL - COL - NAY) | F805: Jose Daniel Trigo Olalde | G805: Madura | H805: =_xlfn.XLOOKUP(A805,Base!A:A,Base!H:H,"Plan") -> Plan | I805: Desincorporado | J805: 45689 | K805: Baja Total
A806: 300795195 | B806: SLP SIX el Rosedal | C806: OCCIDENTE | D806: Ags-Zac-SLP | E806: Maria Eugenia Salazar Leos (SLP-AGS-ZAC) | F806: Francisco Javier Romero Espinosa | G806: Madura | H806: =_xlfn.XLOOKUP(A806,Base!A:A,Base!H:H,"Plan") -> Plan | I806: Desincorporado | J806: 45689 | K806: Baja Total
A807: 300420011 | B807: Tecate Six la Caminera | C807: OCCIDENTE | D807: Jal - Col - Nay | E807: Nancy Velez (JAL - COL - NAY) | F807: Kevin Yovani Parra Gonzalez | G807: Madura | H807: =_xlfn.XLOOKUP(A807,Base!A:A,Base!H:H,"Plan") -> Plan | I807: Desincorporado | J807: 45689 | K807: Baja Total
A808: 301482403 | B808: Jal Six Tepa | C808: OCCIDENTE | D808: Jal - Col - Nay | E808: Nancy Velez (JAL - COL - NAY) | F808: Miguel Hernando Plancarte Lara | G808: Madura | H808: =_xlfn.XLOOKUP(A808,Base!A:A,Base!H:H,"Plan") -> Plan | I808: Desincorporado | J808: 45689 | K808: Baja Total
A809: 300097818 | B809: Tkt Six Salida al Filo | C809: OCCIDENTE | D809: Jal - Col - Nay | E809: Nancy Velez (JAL - COL - NAY) | F809: Ana Laura Villalobos Gutierrez | G809: Madura | H809: =_xlfn.XLOOKUP(A809,Base!A:A,Base!H:H,"Plan") -> Plan | I809: Desincorporado | J809: 45689 | K809: Baja Total
A810: 300804901 | B810: SLP SIX Del Valle | C810: OCCIDENTE | D810: Ags-Zac-SLP | E810: Maria Eugenia Salazar Leos (SLP-AGS-ZAC) | F810: Francisco Javier Romero Espinosa | G810: Madura | H810: =_xlfn.XLOOKUP(A810,Base!A:A,Base!H:H,"Plan") -> Plan | I810: Desincorporado | J810: 45689 | K810: Baja Total
A811: 300799839 | B811: SLP SIX San Lorenzo | C811: OCCIDENTE | D811: Ags-Zac-SLP | E811: Maria Eugenia Salazar Leos (SLP-AGS-ZAC) | F811: Francisco Javier Romero Espinosa | G811: Madura | H811: =_xlfn.XLOOKUP(A811,Base!A:A,Base!H:H,"Plan") -> Plan | I811: Desincorporado | J811: 45689 | K811: Baja Total
...

Sheet Resumen 2023
B2: Closures SIX 2023 | J2: Rango "Base" columna H y columna C
B4: Region | C4: Annual Plan | D4: Real | E4: ∆ | F4: % AP | J4: In Process | K4: ∆ vs AP
B5: NW | C5: =COUNTIF(Plan!$F$3:$F$147,'Resumen 2023'!B5) -> 43 | D5: =+D14 -> 0 | E5: =+C5-D5 -> 43 | F5: =+D5/C5 -> 0 | J5: =COUNTIFS(Base!H:H,"Plan",Base!C:C,'Resumen 2023'!$B5) -> 0 | K5: =+C5-J5-D5 -> 43
B6: NE | C6: =COUNTIF(Plan!$F$3:$F$147,'Resumen 2023'!B6) -> 40 | D6: =+D15 -> 0 | E6: =+C6-D6 -> 40 | F6: =+D6/C6 -> 0 | J6: =COUNTIFS(Base!H:H,"Plan",Base!C:C,'Resumen 2023'!$B6) -> 0 | K6: =+C6-J6-D6 -> 40
B7: WE | C7: =COUNTIF(Plan!$F$3:$F$147,'Resumen 2023'!B7) -> 13 | D7: =+D16 -> 0 | E7: =+C7-D7 -> 13 | F7: =+D7/C7 -> 0 | J7: =COUNTIFS(Base!H:H,"Plan",Base!C:C,'Resumen 2023'!$B7) -> 0 | K7: =+C7-J7-D7 -> 13
B8: CE | C8: =COUNTIF(Plan!$F$3:$F$147,'Resumen 2023'!B8) -> 10 | D8: =+D17 -> 0 | E8: =+C8-D8 -> 10 | F8: =+D8/C8 -> 0 | J8: =COUNTIFS(Base!H:H,"Plan",Base!C:C,'Resumen 2023'!$B8) -> 0 | K8: =+C8-J8-D8 -> 10
B9: SE | C9: =COUNTIF(Plan!$F$3:$F$147,'Resumen 2023'!B9) -> 35 | D9: =+D18 -> 0 | E9: =+C9-D9 -> 35 | F9: =+D9/C9 -> 0 | J9: =COUNTIFS(Base!H:H,"Plan",Base!C:C,'Resumen 2023'!$B9) -> 0 | K9: =+C9-J9-D9 -> 35
B10: SIX | C10: =SUM(C5:C9) -> 141 | D10: =SUM(D5:D9) -> 0 | E10: =SUM(E5:E9) -> 141 | F10: =+D10/C10 -> 0 | J10: =SUM(J5:J9) -> 0 | K10: =+C10-J10-D10 -> 141
B12: Region | C12: Closed | D12: Reason of Closures | J12: Other reason of Closures above AP in process
D13: Plan | E13: Region Plan | F13: Natural | G13: Legal | H13: Insecurity | J13: Natural | K13: Region Plan | L13: Insecurity | M13: Legal | N13: Total
B14: NW | C14: =COUNTIF('Bajas Oficiales'!$C$4:$C$1135,'Resumen 2023'!B14) -> 0 | D14: =COUNTIFS('Bajas Oficiales'!$H$4:$H$1135,'Resumen 2023'!$D$13,'Bajas Oficiales'!$C$4:$C$1135,'Resumen 2023'!$B14) -> 0 | E14: =COUNTIFS('Bajas Oficiales'!$H$4:$H$1135,'Resumen 2023'!$E$13,'Bajas Oficiales'!$C$4:$C$1135,'Resumen 2023'!$B14) -> 0 | F14: =COUNTIFS('Bajas Oficiales'!$H$4:$H$1135,'Resumen 2023'!$F$13,'Bajas Oficiales'!$C$4:$C$1135,'Resumen 2023'!$B14) -> 0 | G14: =COUNTIFS('Bajas Oficiales'!$H$4:$H$1135,'Resumen 2023'!$G$13,'Bajas Oficiales'!$C$4:$C$1135,'Resumen 2023'!$B14) -> 0 | H14: =COUNTIFS('Bajas Oficiales'!$H$4:$H$1135,'Resumen 2023'!$H$13,'Bajas Oficiales'!$C$4:$C$1135,'Resumen 2023'!$B14) -> 0 | J14: =COUNTIFS(Base!H:H,'Resumen 2023'!J$13,Base!C:C,'Resumen 2023'!$B5) -> 13 | K14: =COUNTIFS(Base!#REF!,'Resumen 2023'!K$13,Base!D:D,'Resumen 2023'!$B5) -> #REF! | L14: =COUNTIFS(Base!#REF!,'Resumen 2023'!L$13,Base!E:E,'Resumen 2023'!$B5) -> #REF! | M14: =COUNTIFS(Base!#REF!,'Resumen 2023'!M$13,Base!F:F,'Resumen 2023'!$B5) -> #REF! | N14: =SUM(J14:M14) -> #REF!
B15: NE | C15: =COUNTIF('Bajas Oficiales'!$C$4:$C$1135,'Resumen 2023'!B15) -> 0 | D15: =COUNTIFS('Bajas Oficiales'!$H$4:$H$1135,'Resumen 2023'!$D$13,'Bajas Oficiales'!$C$4:$C$1135,'Resumen 2023'!$B15) -> 0 | E15: =COUNTIFS('Bajas Oficiales'!$H$4:$H$1135,'Resumen 2023'!$E$13,'Bajas Oficiales'!$C$4:$C$1135,'Resumen 2023'!$B15) -> 0 | F15: =COUNTIFS('Bajas Oficiales'!$H$4:$H$1135,'Resumen 2023'!$F$13,'Bajas Oficiales'!$C$4:$C$1135,'Resumen 2023'!$B15) -> 0 | G15: =COUNTIFS('Bajas Oficiales'!$H$4:$H$1135,'Resumen 2023'!$G$13,'Bajas Oficiales'!$C$4:$C$1135,'Resumen 2023'!$B15) -> 0 | H15: =COUNTIFS('Bajas Oficiales'!$H$4:$H$1135,'Resumen 2023'!$H$13,'Bajas Oficiales'!$C$4:$C$1135,'Resumen 2023'!$B15) -> 0 | J15: =COUNTIFS(Base!H:H,'Resumen 2023'!J$13,Base!C:C,'Resumen 2023'!$B6) -> 23 | K15: =COUNTIFS(Base!#REF!,'Resumen 2023'!K$13,Base!D:D,'Resumen 2023'!$B6) -> #REF! | L15: =COUNTIFS(Base!#REF!,'Resumen 2023'!L$13,Base!E:E,'Resumen 2023'!$B6) -> #REF! | M15: =COUNTIFS(Base!#REF!,'Resumen 2023'!M$13,Base!F:F,'Resumen 2023'!$B6) -> #REF! | N15: =SUM(J15:M15) -> #REF!
B16: WE | C16: =COUNTIF('Bajas Oficiales'!$C$4:$C$1135,'Resumen 2023'!B16) -> 0 | D16: =COUNTIFS('Bajas Oficiales'!$H$4:$H$1135,'Resumen 2023'!$D$13,'Bajas Oficiales'!$C$4:$C$1135,'Resumen 2023'!$B16) -> 0 | E16: =COUNTIFS('Bajas Oficiales'!$H$4:$H$1135,'Resumen 2023'!$E$13,'Bajas Oficiales'!$C$4:$C$1135,'Resumen 2023'!$B16) -> 0 | F16: =COUNTIFS('Bajas Oficiales'!$H$4:$H$1135,'Resumen 2023'!$F$13,'Bajas Oficiales'!$C$4:$C$1135,'Resumen 2023'!$B16) -> 0 | G16: =COUNTIFS('Bajas Oficiales'!$H$4:$H$1135,'Resumen 2023'!$G$13,'Bajas Oficiales'!$C$4:$C$1135,'Resumen 2023'!$B16) -> 0 | H16: =COUNTIFS('Bajas Oficiales'!$H$4:$H$1135,'Resumen 2023'!$H$13,'Bajas Oficiales'!$C$4:$C$1135,'Resumen 2023'!$B16) -> 0 | J16: =COUNTIFS(Base!H:H,'Resumen 2023'!J$13,Base!C:C,'Resumen 2023'!$B7) -> 2 | K16: =COUNTIFS(Base!#REF!,'Resumen 2023'!K$13,Base!D:D,'Resumen 2023'!$B7) -> #REF! | L16: =COUNTIFS(Base!#REF!,'Resumen 2023'!L$13,Base!E:E,'Resumen 2023'!$B7) -> #REF! | M16: =COUNTIFS(Base!#REF!,'Resumen 2023'!M$13,Base!F:F,'Resumen 2023'!$B7) -> #REF! | N16: =SUM(J16:M16) -> #REF!
B17: CE | C17: =COUNTIF('Bajas Oficiales'!$C$4:$C$1135,'Resumen 2023'!B17) -> 0 | D17: =COUNTIFS('Bajas Oficiales'!$H$4:$H$1135,'Resumen 2023'!$D$13,'Bajas Oficiales'!$C$4:$C$1135,'Resumen 2023'!$B17) -> 0 | E17: =COUNTIFS('Bajas Oficiales'!$H$4:$H$1135,'Resumen 2023'!$E$13,'Bajas Oficiales'!$C$4:$C$1135,'Resumen 2023'!$B17) -> 0 | F17: =COUNTIFS('Bajas Oficiales'!$H$4:$H$1135,'Resumen 2023'!$F$13,'Bajas Oficiales'!$C$4:$C$1135,'Resumen 2023'!$B17) -> 0 | G17: =COUNTIFS('Bajas Oficiales'!$H$4:$H$1135,'Resumen 2023'!$G$13,'Bajas Oficiales'!$C$4:$C$1135,'Resumen 2023'!$B17) -> 0 | H17: =COUNTIFS('Bajas Oficiales'!$H$4:$H$1135,'Resumen 2023'!$H$13,'Bajas Oficiales'!$C$4:$C$1135,'Resumen 2023'!$B17) -> 0 | J17: =COUNTIFS(Base!H:H,'Resumen 2023'!J$13,Base!C:C,'Resumen 2023'!$B8) -> 4 | K17: =COUNTIFS(Base!#REF!,'Resumen 2023'!K$13,Base!D:D,'Resumen 2023'!$B8) -> #REF! | L17: =COUNTIFS(Base!#REF!,'Resumen 2023'!L$13,Base!E:E,'Resumen 2023'!$B8) -> #REF! | M17: =COUNTIFS(Base!#REF!,'Resumen 2023'!M$13,Base!F:F,'Resumen 2023'!$B8) -> #REF! | N17: =SUM(J17:M17) -> #REF!
B18: SE | C18: =COUNTIF('Bajas Oficiales'!$C$4:$C$1135,'Resumen 2023'!B18) -> 0 | D18: =COUNTIFS('Bajas Oficiales'!$H$4:$H$1135,'Resumen 2023'!$D$13,'Bajas Oficiales'!$C$4:$C$1135,'Resumen 2023'!$B18) -> 0 | E18: =COUNTIFS('Bajas Oficiales'!$H$4:$H$1135,'Resumen 2023'!$E$13,'Bajas Oficiales'!$C$4:$C$1135,'Resumen 2023'!$B18) -> 0 | F18: =COUNTIFS('Bajas Oficiales'!$H$4:$H$1135,'Resumen 2023'!$F$13,'Bajas Oficiales'!$C$4:$C$1135,'Resumen 2023'!$B18) -> 0 | G18: =COUNTIFS('Bajas Oficiales'!$H$4:$H$1135,'Resumen 2023'!$G$13,'Bajas Oficiales'!$C$4:$C$1135,'Resumen 2023'!$B18) -> 0 | H18: =COUNTIFS('Bajas Oficiales'!$H$4:$H$1135,'Resumen 2023'!$H$13,'Bajas Oficiales'!$C$4:$C$1135,'Resumen 2023'!$B18) -> 0 | J18: =COUNTIFS(Base!H:H,'Resumen 2023'!J$13,Base!C:C,'Resumen 2023'!$B9) -> 4 | K18: =COUNTIFS(Base!#REF!,'Resumen 2023'!K$13,Base!D:D,'Resumen 2023'!$B9) -> #REF! | L18: =COUNTIFS(Base!#REF!,'Resumen 2023'!L$13,Base!E:E,'Resumen 2023'!$B9) -> #REF! | M18: =COUNTIFS(Base!#REF!,'Resumen 2023'!M$13,Base!F:F,'Resumen 2023'!$B9) -> #REF! | N18: =SUM(J18:M18) -> #REF!
B19: SIX | C19: =SUM(C14:C18) -> 0 | D19: =SUM(D14:D18) -> 0 | E19: =SUM(E14:E18) -> 0 | F19: =SUM(F14:F18) -> 0 | G19: =SUM(G14:G18) -> 0 | H19: =SUM(H14:H18) -> 0 | J19: =SUM(J14:J18) -> 46 | K19: =SUM(K14:K18) -> #REF! | L19: =SUM(L14:L18) -> #REF! | M19: =SUM(M14:M18) -> #REF! | N19: =SUM(J19:M19) -> #REF!
C21: Rango de Bajas oficales columna C | K21: Rango de "Base" columna H

Sheet PPT Regional
O1: C= Región | P1: H=Tipo cierre
B2: Closures SIX 2024 | E2: Rango "Bajas Oficiales" columna C,D y H | J2: Rango "Base" columna C y H y D | O2: D=Gz
C3: Closed | D3: Reason of Closures | J3: Other reason above AP in Process
B4: Region | D4: Plan | E4: Region Plan | F4: Natural | G4: Legal | H4: Insecurity | J4: Natural | K4: Region Plan | L4: Legal | M4: Insecurity | N4: Total
B5: NW | C5: =COUNTIF('Bajas Oficiales'!$C$4:$C$567,'PPT Regional'!B5) -> 0 | D5: =COUNTIFS('Bajas Oficiales'!$C$4:$C$567,B$5,'Bajas Oficiales'!$H$4:$H$567,'PPT Regional'!D$4) -> 0 | E5: =COUNTIFS('Bajas Oficiales'!$C$4:$C$567,$B5,'Bajas Oficiales'!$H$4:$H$567,'PPT Regional'!E$4) -> 0 | F5: =COUNTIFS('Bajas Oficiales'!$C$4:$C$567,$B5,'Bajas Oficiales'!$H$4:$H$567,'PPT Regional'!F$4) -> 0 | G5: =COUNTIFS('Bajas Oficiales'!$C$4:$C$567,$B5,'Bajas Oficiales'!$H$4:$H$567,'PPT Regional'!G$4) -> 0 | H5: =COUNTIFS('Bajas Oficiales'!$C$4:$C$567,$B5,'Bajas Oficiales'!$H$4:$H$567,'PPT Regional'!H$4) -> 0 | J5: =COUNTIFS(Base!#REF!,$B5,Base!#REF!,'PPT Regional'!J$4) -> #REF! | K5: =COUNTIFS(Base!#REF!,$B5,Base!#REF!,'PPT Regional'!K$4) -> #REF! | L5: =COUNTIFS(Base!#REF!,$B5,Base!#REF!,'PPT Regional'!L$4) -> #REF! | M5: =COUNTIFS(Base!#REF!,$B5,Base!#REF!,'PPT Regional'!M$4) -> #REF! | N5: =SUM(J5:M5) -> #REF!
B6: Baja California Nte | C6: =COUNTIF('Bajas Oficiales'!$D$4:$D$567,'PPT Regional'!B6) -> 17 | D6: =COUNTIFS('Bajas Oficiales'!$D$4:$D$567,'PPT Regional'!$B6,'Bajas Oficiales'!$H$4:$H$567,'PPT Regional'!D$4) -> 13 | E6: =COUNTIFS('Bajas Oficiales'!$D$4:$D$567,'PPT Regional'!$B6,'Bajas Oficiales'!$H$4:$H$567,'PPT Regional'!E$4) -> 0 | F6: =COUNTIFS('Bajas Oficiales'!$D$4:$D$567,'PPT Regional'!$B6,'Bajas Oficiales'!$H$4:$H$567,'PPT Regional'!F$4) -> 4 | G6: =COUNTIFS('Bajas Oficiales'!$D$4:$D$567,'PPT Regional'!$B6,'Bajas Oficiales'!$H$4:$H$567,'PPT Regional'!G$4) -> 0 | H6: =COUNTIFS('Bajas Oficiales'!$D$4:$D$567,'PPT Regional'!$B6,'Bajas Oficiales'!$H$4:$H$567,'PPT Regional'!H$4) -> 0 | J6: =COUNTIFS(Base!H:H,'PPT Regional'!J$4,Base!D:D,'PPT Regional'!$B6) -> 0 | K6: =COUNTIFS(Base!#REF!,'PPT Regional'!K$4,Base!#REF!,'PPT Regional'!$B6) -> #REF! | L6: =COUNTIFS(Base!#REF!,'PPT Regional'!L$4,Base!#REF!,'PPT Regional'!$B6) -> #REF! | M6: =COUNTIFS(Base!#REF!,'PPT Regional'!M$4,Base!#REF!,'PPT Regional'!$B6) -> #REF! | N6: =SUM(J6:M6) -> #REF!
B7: Baja California Sur | C7: =COUNTIF('Bajas Oficiales'!$D$4:$D$567,'PPT Regional'!B7) -> 7 | D7: =COUNTIFS('Bajas Oficiales'!$D$4:$D$567,'PPT Regional'!$B7,'Bajas Oficiales'!$H$4:$H$567,'PPT Regional'!D$4) -> 6 | E7: =COUNTIFS('Bajas Oficiales'!$D$4:$D$567,'PPT Regional'!$B7,'Bajas Oficiales'!$H$4:$H$567,'PPT Regional'!E$4) -> 0 | F7: =COUNTIFS('Bajas Oficiales'!$D$4:$D$567,'PPT Regional'!$B7,'Bajas Oficiales'!$H$4:$H$567,'PPT Regional'!F$4) -> 0 | G7: =COUNTIFS('Bajas Oficiales'!$D$4:$D$567,'PPT Regional'!$B7,'Bajas Oficiales'!$H$4:$H$567,'PPT Regional'!G$4) -> 0 | H7: =COUNTIFS('Bajas Oficiales'!$D$4:$D$567,'PPT Regional'!$B7,'Bajas Oficiales'!$H$4:$H$567,'PPT Regional'!H$4) -> 1 | J7: =COUNTIFS(Base!H:H,'PPT Regional'!J$4,Base!D:D,'PPT Regional'!$B7) -> 0 | K7: =COUNTIFS(Base!#REF!,'PPT Regional'!K$4,Base!#REF!,'PPT Regional'!$B7) -> #REF! | L7: =COUNTIFS(Base!#REF!,'PPT Regional'!L$4,Base!#REF!,'PPT Regional'!$B7) -> #REF! | M7: =COUNTIFS(Base!#REF!,'PPT Regional'!M$4,Base!#REF!,'PPT Regional'!$B7) -> #REF! | N7: =SUM(J7:M7) -> #REF!
B8: Chihuahua | C8: =COUNTIF('Bajas Oficiales'!$D$4:$D$567,'PPT Regional'!B8) -> 17 | D8: =COUNTIFS('Bajas Oficiales'!$D$4:$D$567,'PPT Regional'!$B8,'Bajas Oficiales'!$H$4:$H$567,'PPT Regional'!D$4) -> 15 | E8: =COUNTIFS('Bajas Oficiales'!$D$4:$D$567,'PPT Regional'!$B8,'Bajas Oficiales'!$H$4:$H$567,'PPT Regional'!E$4) -> 0 | F8: =COUNTIFS('Bajas Oficiales'!$D$4:$D$567,'PPT Regional'!$B8,'Bajas Oficiales'!$H$4:$H$567,'PPT Regional'!F$4) -> 2 | G8: =COUNTIFS('Bajas Oficiales'!$D$4:$D$567,'PPT Regional'!$B8,'Bajas Oficiales'!$H$4:$H$567,'PPT Regional'!G$4) -> 0 | H8: =COUNTIFS('Bajas Oficiales'!$D$4:$D$567,'PPT Regional'!$B8,'Bajas Oficiales'!$H$4:$H$567,'PPT Regional'!H$4) -> 0 | J8: =COUNTIFS(Base!H:H,'PPT Regional'!J$4,Base!D:D,'PPT Regional'!$B8) -> 0 | K8: =COUNTIFS(Base!#REF!,'PPT Regional'!K$4,Base!#REF!,'PPT Regional'!$B8) -> #REF! | L8: =COUNTIFS(Base!#REF!,'PPT Regional'!L$4,Base!#REF!,'PPT Regional'!$B8) -> #REF! | M8: =COUNTIFS(Base!#REF!,'PPT Regional'!M$4,Base!#REF!,'PPT Regional'!$B8) -> #REF! | N8: =SUM(J8:M8) -> #REF!
B9: Juárez | C9: =COUNTIF('Bajas Oficiales'!$D$4:$D$567,'PPT Regional'!B9) -> 7 | D9: =COUNTIFS('Bajas Oficiales'!$D$4:$D$567,'PPT Regional'!$B9,'Bajas Oficiales'!$H$4:$H$567,'PPT Regional'!D$4) -> 5 | E9: =COUNTIFS('Bajas Oficiales'!$D$4:$D$567,'PPT Regional'!$B9,'Bajas Oficiales'!$H$4:$H$567,'PPT Regional'!E$4) -> 0 | F9: =COUNTIFS('Bajas Oficiales'!$D$4:$D$567,'PPT Regional'!$B9,'Bajas Oficiales'!$H$4:$H$567,'PPT Regional'!F$4) -> 2 | G9: =COUNTIFS('Bajas Oficiales'!$D$4:$D$567,'PPT Regional'!$B9,'Bajas Oficiales'!$H$4:$H$567,'PPT Regional'!G$4) -> 0 | H9: =COUNTIFS('Bajas Oficiales'!$D$4:$D$567,'PPT Regional'!$B9,'Bajas Oficiales'!$H$4:$H$567,'PPT Regional'!H$4) -> 0 | J9: =COUNTIFS(Base!H:H,'PPT Regional'!J$4,Base!D:D,'PPT Regional'!$B9) -> 0 | K9: =COUNTIFS(Base!#REF!,'PPT Regional'!K$4,Base!#REF!,'PPT Regional'!$B9) -> #REF! | L9: =COUNTIFS(Base!#REF!,'PPT Regional'!L$4,Base!#REF!,'PPT Regional'!$B9) -> #REF! | M9: =COUNTIFS(Base!#REF!,'PPT Regional'!M$4,Base!#REF!,'PPT Regional'!$B9) -> #REF! | N9: =SUM(J9:M9) -> #REF!
B10: Sinaloa | C10: =COUNTIF('Bajas Oficiales'!$D$4:$D$567,'PPT Regional'!B10) -> 35 | D10: =COUNTIFS('Bajas Oficiales'!$D$4:$D$567,'PPT Regional'!$B10,'Bajas Oficiales'!$H$4:$H$567,'PPT Regional'!D$4) -> 31 | E10: =COUNTIFS('Bajas Oficiales'!$D$4:$D$567,'PPT Regional'!$B10,'Bajas Oficiales'!$H$4:$H$567,'PPT Regional'!E$4) -> 0 | F10: =COUNTIFS('Bajas Oficiales'!$D$4:$D$567,'PPT Regional'!$B10,'Bajas Oficiales'!$H$4:$H$567,'PPT Regional'!F$4) -> 4 | G10: =COUNTIFS('Bajas Oficiales'!$D$4:$D$567,'PPT Regional'!$B10,'Bajas Oficiales'!$H$4:$H$567,'PPT Regional'!G$4) -> 0 | H10: =COUNTIFS('Bajas Oficiales'!$D$4:$D$567,'PPT Regional'!$B10,'Bajas Oficiales'!$H$4:$H$567,'PPT Regional'!H$4) -> 0 | J10: =COUNTIFS(Base!H:H,'PPT Regional'!J$4,Base!D:D,'PPT Regional'!$B10) -> 0 | K10: =COUNTIFS(Base!#REF!,'PPT Regional'!K$4,Base!#REF!,'PPT Regional'!$B10) -> #REF! | L10: =COUNTIFS(Base!#REF!,'PPT Regional'!L$4,Base!#REF!,'PPT Regional'!$B10) -> #REF! | M10: =COUNTIFS(Base!#REF!,'PPT Regional'!M$4,Base!#REF!,'PPT Regional'!$B10) -> #REF! | N10: =SUM(J10:M10) -> #REF!
B11: Sonora | C11: =COUNTIF('Bajas Oficiales'!$D$4:$D$567,'PPT Regional'!B11) -> 16 | D11: =COUNTIFS('Bajas Oficiales'!$D$4:$D$567,'PPT Regional'!$B11,'Bajas Oficiales'!$H$4:$H$567,'PPT Regional'!D$4) -> 14 | E11: =COUNTIFS('Bajas Oficiales'!$D$4:$D$567,'PPT Regional'!$B11,'Bajas Oficiales'!$H$4:$H$567,'PPT Regional'!E$4) -> 0 | F11: =COUNTIFS('Bajas Oficiales'!$D$4:$D$567,'PPT Regional'!$B11,'Bajas Oficiales'!$H$4:$H$567,'PPT Regional'!F$4) -> 2 | G11: =COUNTIFS('Bajas Oficiales'!$D$4:$D$567,'PPT Regional'!$B11,'Bajas Oficiales'!$H$4:$H$567,'PPT Regional'!G$4) -> 0 | H11: =COUNTIFS('Bajas Oficiales'!$D$4:$D$567,'PPT Regional'!$B11,'Bajas Oficiales'!$H$4:$H$567,'PPT Regional'!H$4) -> 0 | J11: =COUNTIFS(Base!H:H,'PPT Regional'!J$4,Base!D:D,'PPT Regional'!$B11) -> 0 | K11: =COUNTIFS(Base!#REF!,'PPT Regional'!K$4,Base!#REF!,'PPT Regional'!$B11) -> #REF! | L11: =COUNTIFS(Base!#REF!,'PPT Regional'!L$4,Base!#REF!,'PPT Regional'!$B11) -> #REF! | M11: =COUNTIFS(Base!#REF!,'PPT Regional'!M$4,Base!#REF!,'PPT Regional'!$B11) -> #REF! | N11: =SUM(J11:M11) -> #REF!
B12: NE | C12: =COUNTIF('Bajas Oficiales'!$C$4:$C$567,'PPT Regional'!B12) -> 0 | D12: =COUNTIFS('Bajas Oficiales'!$C$4:$C$567,B12,'Bajas Oficiales'!$H$4:$H$567,'PPT Regional'!D$4) -> 0 | E12: =COUNTIFS('Bajas Oficiales'!$C$4:$C$567,$B12,'Bajas Oficiales'!$H$4:$H$567,'PPT Regional'!E$4) -> 0 | F12: =COUNTIFS('Bajas Oficiales'!$C$4:$C$567,$B12,'Bajas Oficiales'!$H$4:$H$567,'PPT Regional'!F$4) -> 0 | G12: =COUNTIFS('Bajas Oficiales'!$C$4:$C$567,$B12,'Bajas Oficiales'!$H$4:$H$567,'PPT Regional'!G$4) -> 0 | H12: =COUNTIFS('Bajas Oficiales'!$C$4:$C$567,$B12,'Bajas Oficiales'!$H$4:$H$567,'PPT Regional'!H$4) -> 0 | J12: =COUNTIFS(Base!#REF!,$B12,Base!#REF!,'PPT Regional'!J$4) -> #REF! | K12: =COUNTIFS(Base!#REF!,$B12,Base!#REF!,'PPT Regional'!K$4) -> #REF! | L12: =COUNTIFS(Base!#REF!,$B12,Base!#REF!,'PPT Regional'!L$4) -> #REF! | M12: =COUNTIFS(Base!#REF!,$B12,Base!#REF!,'PPT Regional'!M$4) -> #REF! | N12: =SUM(J12:M12) -> #REF!
B13: Coahuila | C13: =COUNTIF('Bajas Oficiales'!$D$4:$D$567,'PPT Regional'!B13) -> 43 | D13: =COUNTIFS('Bajas Oficiales'!$D$4:$D$567,'PPT Regional'!$B13,'Bajas Oficiales'!$H$4:$H$567,'PPT Regional'!D$4) -> 29 | E13: =COUNTIFS('Bajas Oficiales'!$D$4:$D$567,'PPT Regional'!$B13,'Bajas Oficiales'!$H$4:$H$567,'PPT Regional'!E$4) -> 4 | F13: =COUNTIFS('Bajas Oficiales'!$D$4:$D$567,'PPT Regional'!$B13,'Bajas Oficiales'!$H$4:$H$567,'PPT Regional'!F$4) -> 1 | G13: =COUNTIFS('Bajas Oficiales'!$D$4:$D$567,'PPT Regional'!$B13,'Bajas Oficiales'!$H$4:$H$567,'PPT Regional'!G$4) -> 9 | H13: =COUNTIFS('Bajas Oficiales'!$D$4:$D$567,'PPT Regional'!$B13,'Bajas Oficiales'!$H$4:$H$567,'PPT Regional'!H$4) -> 0 | J13: =COUNTIFS(Base!#REF!,'PPT Regional'!J$4,Base!#REF!,'PPT Regional'!$B13) -> #REF! | K13: =COUNTIFS(Base!#REF!,'PPT Regional'!K$4,Base!#REF!,'PPT Regional'!$B13) -> #REF! | L13: =COUNTIFS(Base!#REF!,'PPT Regional'!L$4,Base!#REF!,'PPT Regional'!$B13) -> #REF! | M13: =COUNTIFS(Base!#REF!,'PPT Regional'!M$4,Base!#REF!,'PPT Regional'!$B13) -> #REF! | N13: =SUM(J13:M13) -> #REF!
B14: Durango | C14: =COUNTIF('Bajas Oficiales'!$D$4:$D$567,'PPT Regional'!B14) -> 4 | D14: =COUNTIFS('Bajas Oficiales'!$D$4:$D$567,'PPT Regional'!$B14,'Bajas Oficiales'!$H$4:$H$567,'PPT Regional'!D$4) -> 3 | E14: =COUNTIFS('Bajas Oficiales'!$D$4:$D$567,'PPT Regional'!$B14,'Bajas Oficiales'!$H$4:$H$567,'PPT Regional'!E$4) -> 1 | F14: =COUNTIFS('Bajas Oficiales'!$D$4:$D$567,'PPT Regional'!$B14,'Bajas Oficiales'!$H$4:$H$567,'PPT Regional'!F$4) -> 0 | G14: =COUNTIFS('Bajas Oficiales'!$D$4:$D$567,'PPT Regional'!$B14,'Bajas Oficiales'!$H$4:$H$567,'PPT Regional'!G$4) -> 0 | H14: =COUNTIFS('Bajas Oficiales'!$D$4:$D$567,'PPT Regional'!$B14,'Bajas Oficiales'!$H$4:$H$567,'PPT Regional'!H$4) -> 0 | J14: =COUNTIFS(Base!#REF!,'PPT Regional'!J$4,Base!#REF!,'PPT Regional'!$B14) -> #REF! | K14: =COUNTIFS(Base!#REF!,'PPT Regional'!K$4,Base!#REF!,'PPT Regional'!$B14) -> #REF! | L14: =COUNTIFS(Base!#REF!,'PPT Regional'!L$4,Base!#REF!,'PPT Regional'!$B14) -> #REF! | M14: =COUNTIFS(Base!#REF!,'PPT Regional'!M$4,Base!#REF!,'PPT Regional'!$B14) -> #REF! | N14: =SUM(J14:M14) -> #REF!
B15: Nuevo León | C15: =COUNTIF('Bajas Oficiales'!$D$4:$D$567,'PPT Regional'!B15) -> 87 | D15: =COUNTIFS('Bajas Oficiales'!$D$4:$D$567,'PPT Regional'!$B15,'Bajas Oficiales'!$H$4:$H$567,'PPT Regional'!D$4) -> 70 | E15: =COUNTIFS('Bajas Oficiales'!$D$4:$D$567,'PPT Regional'!$B15,'Bajas Oficiales'!$H$4:$H$567,'PPT Regional'!E$4) -> 2 | F15: =COUNTIFS('Bajas Oficiales'!$D$4:$D$567,'PPT Regional'!$B15,'Bajas Oficiales'!$H$4:$H$567,'PPT Regional'!F$4) -> 1 | G15: =COUNTIFS('Bajas Oficiales'!$D$4:$D$567,'PPT Regional'!$B15,'Bajas Oficiales'!$H$4:$H$567,'PPT Regional'!G$4) -> 12 | H15: =COUNTIFS('Bajas Oficiales'!$D$4:$D$567,'PPT Regional'!$B15,'Bajas Oficiales'!$H$4:$H$567,'PPT Regional'!H$4) -> 2 | J15: =COUNTIFS(Base!#REF!,'PPT Regional'!J$4,Base!#REF!,'PPT Regional'!$B15) -> #REF! | K15: =COUNTIFS(Base!#REF!,'PPT Regional'!K$4,Base!#REF!,'PPT Regional'!$B15) -> #REF! | L15: =COUNTIFS(Base!#REF!,'PPT Regional'!L$4,Base!#REF!,'PPT Regional'!$B15) -> #REF! | M15: =COUNTIFS(Base!#REF!,'PPT Regional'!M$4,Base!#REF!,'PPT Regional'!$B15) -> #REF! | N15: =SUM(J15:M15) -> #REF!
B16: Tamaulipas Nte | C16: =COUNTIF('Bajas Oficiales'!$D$4:$D$567,'PPT Regional'!B16) -> 19 | D16: =COUNTIFS('Bajas Oficiales'!$D$4:$D$567,'PPT Regional'!$B16,'Bajas Oficiales'!$H$4:$H$567,'PPT Regional'!D$4) -> 8 | E16: =COUNTIFS('Bajas Oficiales'!$D$4:$D$567,'PPT Regional'!$B16,'Bajas Oficiales'!$H$4:$H$567,'PPT Regional'!E$4) -> 0 | F16: =COUNTIFS('Bajas Oficiales'!$D$4:$D$567,'PPT Regional'!$B16,'Bajas Oficiales'!$H$4:$H$567,'PPT Regional'!F$4) -> 0 | G16: =COUNTIFS('Bajas Oficiales'!$D$4:$D$567,'PPT Regional'!$B16,'Bajas Oficiales'!$H$4:$H$567,'PPT Regional'!G$4) -> 11 | H16: =COUNTIFS('Bajas Oficiales'!$D$4:$D$567,'PPT Regional'!$B16,'Bajas Oficiales'!$H$4:$H$567,'PPT Regional'!H$4) -> 0 | J16: =COUNTIFS(Base!#REF!,'PPT Regional'!J$4,Base!#REF!,'PPT Regional'!$B16) -> #REF! | K16: =COUNTIFS(Base!#REF!,'PPT Regional'!K$4,Base!#REF!,'PPT Regional'!$B16) -> #REF! | L16: =COUNTIFS(Base!#REF!,'PPT Regional'!L$4,Base!#REF!,'PPT Regional'!$B16) -> #REF! | M16: =COUNTIFS(Base!#REF!,'PPT Regional'!M$4,Base!#REF!,'PPT Regional'!$B16) -> #REF! | N16: =SUM(J16:M16) -> #REF!
B17: Tamps Sur/Ver Nte | C17: =COUNTIF('Bajas Oficiales'!$D$4:$D$567,'PPT Regional'!B17) -> 19 | D17: =COUNTIFS('Bajas Oficiales'!$D$4:$D$567,'PPT Regional'!$B17,'Bajas Oficiales'!$H$4:$H$567,'PPT Regional'!D$4) -> 7 | E17: =COUNTIFS('Bajas Oficiales'!$D$4:$D$567,'PPT Regional'!$B17,'Bajas Oficiales'!$H$4:$H$567,'PPT Regional'!E$4) -> 0 | F17: =COUNTIFS('Bajas Oficiales'!$D$4:$D$567,'PPT Regional'!$B17,'Bajas Oficiales'!$H$4:$H$567,'PPT Regional'!F$4) -> 1 | G17: =COUNTIFS('Bajas Oficiales'!$D$4:$D$567,'PPT Regional'!$B17,'Bajas Oficiales'!$H$4:$H$567,'PPT Regional'!G$4) -> 8 | H17: =COUNTIFS('Bajas Oficiales'!$D$4:$D$567,'PPT Regional'!$B17,'Bajas Oficiales'!$H$4:$H$567,'PPT Regional'!H$4) -> 0 | J17: =COUNTIFS(Base!#REF!,'PPT Regional'!J$4,Base!#REF!,'PPT Regional'!$B17) -> #REF! | K17: =COUNTIFS(Base!#REF!,'PPT Regional'!K$4,Base!#REF!,'PPT Regional'!$B17) -> #REF! | L17: =COUNTIFS(Base!#REF!,'PPT Regional'!L$4,Base!#REF!,'PPT Regional'!$B17) -> #REF! | M17: =COUNTIFS(Base!#REF!,'PPT Regional'!M$4,Base!#REF!,'PPT Regional'!$B17) -> #REF! | N17: =SUM(J17:M17) -> #REF!
B18: WE | C18: =COUNTIF('Bajas Oficiales'!$C$4:$C$567,'PPT Regional'!B18) -> 0 | D18: =COUNTIFS('Bajas Oficiales'!$C$4:$C$567,B18,'Bajas Oficiales'!$H$4:$H$567,'PPT Regional'!D$4) -> 0 | E18: =COUNTIFS('Bajas Oficiales'!$C$4:$C$567,$B18,'Bajas Oficiales'!$H$4:$H$567,'PPT Regional'!E$4) -> 0 | F18: =COUNTIFS('Bajas Oficiales'!$C$4:$C$567,$B18,'Bajas Oficiales'!$H$4:$H$567,'PPT Regional'!F$4) -> 0 | G18: =COUNTIFS('Bajas Oficiales'!$C$4:$C$567,$B18,'Bajas Oficiales'!$H$4:$H$567,'PPT Regional'!G$4) -> 0 | H18: =COUNTIFS('Bajas Oficiales'!$C$4:$C$567,$B18,'Bajas Oficiales'!$H$4:$H$567,'PPT Regional'!H$4) -> 0 | J18: =COUNTIFS(Base!#REF!,$B18,Base!#REF!,'PPT Regional'!J$4) -> #REF! | K18: =COUNTIFS(Base!#REF!,$B18,Base!#REF!,'PPT Regional'!K$4) -> #REF! | L18: =COUNTIFS(Base!#REF!,$B18,Base!#REF!,'PPT Regional'!L$4) -> #REF! | M18: =COUNTIFS(Base!#REF!,$B18,Base!#REF!,'PPT Regional'!M$4) -> #REF! | N18: =SUM(J18:M18) -> #REF!
B19: Ags-Zac-SLP | C19: =COUNTIF('Bajas Oficiales'!$D$4:$D$567,'PPT Regional'!B19) -> 9 | D19: =COUNTIFS('Bajas Oficiales'!$D$4:$D$567,'PPT Regional'!$B19,'Bajas Oficiales'!$H$4:$H$567,'PPT Regional'!D$4) -> 9 | E19: =COUNTIFS('Bajas Oficiales'!$D$4:$D$567,'PPT Regional'!$B19,'Bajas Oficiales'!$H$4:$H$567,'PPT Regional'!E$4) -> 0 | F19: =COUNTIFS('Bajas Oficiales'!$D$4:$D$567,'PPT Regional'!$B19,'Bajas Oficiales'!$H$4:$H$567,'PPT Regional'!F$4) -> 0 | G19: =COUNTIFS('Bajas Oficiales'!$D$4:$D$567,'PPT Regional'!$B19,'Bajas Oficiales'!$H$4:$H$567,'PPT Regional'!G$4) -> 0 | H19: =COUNTIFS('Bajas Oficiales'!$D$4:$D$567,'PPT Regional'!$B19,'Bajas Oficiales'!$H$4:$H$567,'PPT Regional'!H$4) -> 0 | J19: =COUNTIFS(Base!#REF!,'PPT Regional'!J$4,Base!#REF!,'PPT Regional'!$B19) -> #REF! | K19: =COUNTIFS(Base!#REF!,'PPT Regional'!K$4,Base!#REF!,'PPT Regional'!$B19) -> #REF! | L19: =COUNTIFS(Base!#REF!,'PPT Regional'!L$4,Base!#REF!,'PPT Regional'!$B19) -> #REF! | M19: =COUNTIFS(Base!#REF!,'PPT Regional'!M$4,Base!#REF!,'PPT Regional'!$B19) -> #REF! | N19: =SUM(J19:M19) -> #REF!
B20: Guanajuato - Querétaro | C20: =COUNTIF('Bajas Oficiales'!$D$4:$D$567,'PPT Regional'!B20) -> 2 | D20: =COUNTIFS('Bajas Oficiales'!$D$4:$D$567,'PPT Regional'!$B20,'Bajas Oficiales'!$H$4:$H$567,'PPT Regional'!D$4) -> 2 | E20: =COUNTIFS('Bajas Oficiales'!$D$4:$D$567,'PPT Regional'!$B20,'Bajas Oficiales'!$H$4:$H$567,'PPT Regional'!E$4) -> 0 | F20: =COUNTIFS('Bajas Oficiales'!$D$4:$D$567,'PPT Regional'!$B20,'Bajas Oficiales'!$H$4:$H$567,'PPT Regional'!F$4) -> 0 | G20: =COUNTIFS('Bajas Oficiales'!$D$4:$D$567,'PPT Regional'!$B20,'Bajas Oficiales'!$H$4:$H$567,'PPT Regional'!G$4) -> 0 | H20: =COUNTIFS('Bajas Oficiales'!$D$4:$D$567,'PPT Regional'!$B20,'Bajas Oficiales'!$H$4:$H$567,'PPT Regional'!H$4) -> 0 | J20: =COUNTIFS(Base!#REF!,'PPT Regional'!J$4,Base!#REF!,'PPT Regional'!$B20) -> #REF! | K20: =COUNTIFS(Base!#REF!,'PPT Regional'!K$4,Base!#REF!,'PPT Regional'!$B20) -> #REF! | L20: =COUNTIFS(Base!#REF!,'PPT Regional'!L$4,Base!#REF!,'PPT Regional'!$B20) -> #REF! | M20: =COUNTIFS(Base!#REF!,'PPT Regional'!M$4,Base!#REF!,'PPT Regional'!$B20) -> #REF! | N20: =SUM(J20:M20) -> #REF!
B21: Jal - Col - Nay | C21: =COUNTIF('Bajas Oficiales'!$D$4:$D$567,'PPT Regional'!B21) -> 34 | D21: =COUNTIFS('Bajas Oficiales'!$D$4:$D$567,'PPT Regional'!$B21,'Bajas Oficiales'!$H$4:$H$567,'PPT Regional'!D$4) -> 7 | E21: =COUNTIFS('Bajas Oficiales'!$D$4:$D$567,'PPT Regional'!$B21,'Bajas Oficiales'!$H$4:$H$567,'PPT Regional'!E$4) -> 0 | F21: =COUNTIFS('Bajas Oficiales'!$D$4:$D$567,'PPT Regional'!$B21,'Bajas Oficiales'!$H$4:$H$567,'PPT Regional'!F$4) -> 25 | G21: =COUNTIFS('Bajas Oficiales'!$D$4:$D$567,'PPT Regional'!$B21,'Bajas Oficiales'!$H$4:$H$567,'PPT Regional'!G$4) -> 2 | H21: =COUNTIFS('Bajas Oficiales'!$D$4:$D$567,'PPT Regional'!$B21,'Bajas Oficiales'!$H$4:$H$567,'PPT Regional'!H$4) -> 0 | J21: =COUNTIFS(Base!#REF!,'PPT Regional'!J$4,Base!#REF!,'PPT Regional'!$B21) -> #REF! | K21: =COUNTIFS(Base!#REF!,'PPT Regional'!K$4,Base!#REF!,'PPT Regional'!$B21) -> #REF! | L21: =COUNTIFS(Base!#REF!,'PPT Regional'!L$4,Base!#REF!,'PPT Regional'!$B21) -> #REF! | M21: =COUNTIFS(Base!#REF!,'PPT Regional'!M$4,Base!#REF!,'PPT Regional'!$B21) -> #REF! | N21: =SUM(J21:M21) -> #REF!
B22: Michoacán | C22: =COUNTIF('Bajas Oficiales'!$D$4:$D$567,'PPT Regional'!B22) -> 4 | D22: =COUNTIFS('Bajas Oficiales'!$D$4:$D$567,'PPT Regional'!$B22,'Bajas Oficiales'!$H$4:$H$567,'PPT Regional'!D$4) -> 3 | E22: =COUNTIFS('Bajas Oficiales'!$D$4:$D$567,'PPT Regional'!$B22,'Bajas Oficiales'!$H$4:$H$567,'PPT Regional'!E$4) -> 0 | F22: =COUNTIFS('Bajas Oficiales'!$D$4:$D$567,'PPT Regional'!$B22,'Bajas Oficiales'!$H$4:$H$567,'PPT Regional'!F$4) -> 0 | G22: =COUNTIFS('Bajas Oficiales'!$D$4:$D$567,'PPT Regional'!$B22,'Bajas Oficiales'!$H$4:$H$567,'PPT Regional'!G$4) -> 1 | H22: =COUNTIFS('Bajas Oficiales'!$D$4:$D$567,'PPT Regional'!$B22,'Bajas Oficiales'!$H$4:$H$567,'PPT Regional'!H$4) -> 0 | J22: =COUNTIFS(Base!#REF!,'PPT Regional'!J$4,Base!#REF!,'PPT Regional'!$B22) -> #REF! | K22: =COUNTIFS(Base!#REF!,'PPT Regional'!K$4,Base!#REF!,'PPT Regional'!$B22) -> #REF! | L22: =COUNTIFS(Base!#REF!,'PPT Regional'!L$4,Base!#REF!,'PPT Regional'!$B22) -> #REF! | M22: =COUNTIFS(Base!#REF!,'PPT Regional'!M$4,Base!#REF!,'PPT Regional'!$B22) -> #REF! | N22: =SUM(J22:M22) -> #REF!
B23: CE | C23: =COUNTIF('Bajas Oficiales'!$C$4:$C$567,'PPT Regional'!B23) -> 0 | D23: =COUNTIFS('Bajas Oficiales'!$C$4:$C$567,B23,'Bajas Oficiales'!$H$4:$H$567,'PPT Regional'!D$4) -> 0 | E23: =COUNTIFS('Bajas Oficiales'!$C$4:$C$567,$B23,'Bajas Oficiales'!$H$4:$H$567,'PPT Regional'!E$4) -> 0 | F23: =COUNTIFS('Bajas Oficiales'!$C$4:$C$567,$B23,'Bajas Oficiales'!$H$4:$H$567,'PPT Regional'!F$4) -> 0 | G23: =COUNTIFS('Bajas Oficiales'!$C$4:$C$567,$B23,'Bajas Oficiales'!$H$4:$H$567,'PPT Regional'!G$4) -> 0 | H23: =COUNTIFS('Bajas Oficiales'!$C$4:$C$567,$B23,'Bajas Oficiales'!$H$4:$H$567,'PPT Regional'!H$4) -> 0 | J23: =COUNTIFS(Base!#REF!,$B23,Base!#REF!,'PPT Regional'!J$4) -> #REF! | K23: =COUNTIFS(Base!#REF!,$B23,Base!#REF!,'PPT Regional'!K$4) -> #REF! | L23: =COUNTIFS(Base!#REF!,$B23,Base!#REF!,'PPT Regional'!L$4) -> #REF! | M23: =COUNTIFS(Base!#REF!,$B23,Base!#REF!,'PPT Regional'!M$4) -> #REF! | N23: =SUM(J23:M23) -> #REF!
B24: Estado de México | C24: =COUNTIF('Bajas Oficiales'!$D$4:$D$567,'PPT Regional'!B24) -> 5 | D24: =COUNTIFS('Bajas Oficiales'!$D$4:$D$567,'PPT Regional'!$B24,'Bajas Oficiales'!$H$4:$H$567,'PPT Regional'!D$4) -> 0 | E24: =COUNTIFS('Bajas Oficiales'!$D$4:$D$567,'PPT Regional'!$B24,'Bajas Oficiales'!$H$4:$H$567,'PPT Regional'!E$4) -> 1 | F24: =COUNTIFS('Bajas Oficiales'!$D$4:$D$567,'PPT Regional'!$B24,'Bajas Oficiales'!$H$4:$H$567,'PPT Regional'!F$4) -> 2 | G24: =COUNTIFS('Bajas Oficiales'!$D$4:$D$567,'PPT Regional'!$B24,'Bajas Oficiales'!$H$4:$H$567,'PPT Regional'!G$4) -> 0 | H24: =COUNTIFS('Bajas Oficiales'!$D$4:$D$567,'PPT Regional'!$B24,'Bajas Oficiales'!$H$4:$H$567,'PPT Regional'!H$4) -> 2 | J24: =COUNTIFS(Base!#REF!,'PPT Regional'!J$4,Base!#REF!,'PPT Regional'!$B24) -> #REF! | K24: =COUNTIFS(Base!#REF!,'PPT Regional'!K$4,Base!#REF!,'PPT Regional'!$B24) -> #REF! | L24: =COUNTIFS(Base!#REF!,'PPT Regional'!L$4,Base!#REF!,'PPT Regional'!$B24) -> #REF! | M24: =COUNTIFS(Base!#REF!,'PPT Regional'!M$4,Base!#REF!,'PPT Regional'!$B24) -> #REF! | N24: =SUM(J24:M24) -> #REF!
